[2025-05-26T17:53:18.755+0300] {task_context_logger.py:104} ERROR - Executor reports task instance <TaskInstance: currency_etl_dag.fetch_and_store_currency manual__2025-05-26T14:53:15+00:00 [queued]> finished (failed) although the task says it's queued. (Info: None) Was the task killed externally?
